from django.contrib.auth import get_user_model
from rest_framework import serializers
from rest_framework.relations import SlugRelatedField
from rest_framework.validators import UniqueTogetherValidator

from posts.models import Comment, Follow, Group, Post

User = get_user_model()


class PostSerializer(serializers.ModelSerializer):
    """Сериализатор для постов"""
    author = SlugRelatedField(slug_field='username', read_only=True)

    class Meta:
        fields = '__all__'
        model = Post


class CommentSerializer(serializers.ModelSerializer):
    """Сериализатор для комментариев"""
    author = serializers.SlugRelatedField(
        read_only=True, slug_field='username'
    )
    post = serializers.PrimaryKeyRelatedField(read_only=True)

    class Meta:
        fields = '__all__'
        model = Comment


class GroupSerializer(serializers.ModelSerializer):
    """Сериализатор для групп"""
    class Meta:
        fields = '__all__'
        model = Group


class FollowSerializer(serializers.ModelSerializer):
    """Сериализатор для подписок"""
    user = serializers.SlugRelatedField(
        read_only=True,
        default=serializers.CurrentUserDefault(),
        slug_field='username'
    )
    following = serializers.SlugRelatedField(
        queryset=User.objects.all(),
        slug_field='username',
        required=True
    )

    class Meta:
        fields = ('user', 'following')
        model = Follow

        validators = [
            UniqueTogetherValidator(
                queryset=Follow.objects.all(),
                fields=('user', 'following')
            )
        ]

    def validate(self, data):
        if self.context['request'].user == data['following']:
            raise serializers.ValidationError(
                'Нальзя подписываться на самого себя'
            )
        return data
